Workbook

Sheet 01_README
A1: FMCG Sales Performance & Target Tracking System
A2: Excel 2019 Portfolio Project - Synthetic & Illustrative Data
A4: Project Overview
A5: This workbook demonstrates an end-to-end FMCG sales performance and target tracking system built in Microsoft Excel 2019. The model covers company-to-distributor primary sales, salesperson targets, distributor stock, collections, product performance, forecasting, and management reporting.
A7: Portfolio Data Disclaimer
A8: This portfolio project is based on real-world FMCG sales reporting and analytical responsibilities previously performed by the author. All company names, customer/distributor names, products, transactions, targets, inventory records, collection records, and financial figures in this workbook are synthetic and illustrative. The workbook does not reproduce or disclose confidential employer data.
A10: Business Scope
A11: Sales Scope: Company-to-Distributor Primary Sales (Sell-In)
A12: Secondary Sales Available: No — distributor-to-retailer sell-out data is not included.
A13: Inventory Scope: Distributor Stock / Inventory Snapshots
A14: Reporting Period: 2026
A15: Forecast Horizon: 3 Months
... A49: 18_Model_Documentation — Technical model documentation, methodology, formula library, and automation notes

Sheet 02_Control_Panel
A1: Section 1 — Model Controls
A2: Parameter | B2: Value | C2: Description
A3: Reporting Year | B3: 2026 | C3: Primary reporting year for the portfolio model
A4: Latest Actual Month | B4: 46382 | C4: Latest month with actual company-to-distributor sales
A5: Latest Inventory Snapshot | B5: 46387 | C5: Latest distributor inventory snapshot used in analysis
A6: Forecast Horizon (Months) | B6: 3 | C6: Number of future months included in the forecast
A7: Near Target Threshold | B7: 0.9 | C7: Changeable threshold. Achievement at or above this level is classified as Near Target when the Target Achievement Threshold has not been reached.
A8: Target Achievement Threshold | B8: 1 | C8: Changeable threshold. Achievement at or above this level is classified as Achieved.
A9: Forecast Method | B9: 3-Month Rolling Average — Recursive Forecast | C9: Forecast method used for 2027 planning estimates
A10: Section 2 — Model Statistics
A11: Number of Cities | B11: =COUNTA(tblCities[City ID]) -> 4 | C11: Number of cities currently included in the model
A12: Number of RSMs | B12: =SUMPRODUCT((tblSalesTeam[RSM ID]<>"")/COUNTIF(tblSalesTeam[RSM ID],tblSalesTeam[RSM ID]&"")) -> 4 | C12: Number of Regional Sales Managers currently included
A13: Number of Salespeople | B13: =COUNTA(tblSalesTeam[Salesperson ID]) -> 12 | C13: Number of salespeople currently included
A14: Number of Distributors | B14: =COUNTA(tblDistributors[Distributor ID]) -> 12 | C14: Number of active distributors currently included
A15: Number of Products | B15: =COUNTA(tblProducts[Product ID]) -> 56 | C15: Number of products/SKUs currently included
A16: Sales Transactions | B16: =COUNTA(tblSalesTransactions[Transaction ID]) -> 300 | C16: Number of company-to-distributor sales transactions
A17: Collection Records | B17: =COUNTA(tblCollections[Collection ID]) -> 72 | C17: Number of distributor collection records
A18: Inventory Records | B18: =COUNTA(tblInventory[Distributor ID]) -> 192 | C18: 12 distributors × 4 quarterly snapshots × 4 selected SKUs = 192 inventory records
A19: Sales Target Records | B19: =COUNTA(tblSalesTargets[Salesperson ID]) -> 144 | C19: Number of monthly salesperson target records for 2026
A20: Portfolio & Business Scope
A21: Data Type | B21: Synthetic / Illustrative | C21: Portfolio dataset created for demonstration; workflow and business context are based on real-world FMCG reporting experience
A22: Sales Scope | B22: Company-to-Distributor Primary Sales | C22: Sales represent company sell-in to distributors
A23: Secondary Sales Available | B23: No | C23: Distributor-to-retailer sell-out data is not included
A24: Inventory Scope | B24: Distributor Stock | C24: Inventory represents distributor stock snapshots
A25: Forecast Status | B25: Indicative Planning Estimate | C25: Forecast is an illustrative planning estimate and is not a guaranteed future result
A26: Control Usage
A27: Control parameters are linked to model calculations where applicable. Near Target Threshold, Target Achievement Threshold, and Latest Inventory Snapshot directly influence model calculations. Model statistics are automatically derived from the underlying Excel Tables. Reporting Year, Forecast Horizon, and Forecast Method document the model scope and assumptions and do not independently rebuild the underlying dataset.
A28: Portfolio Data Disclaimer
A29: This portfolio project is based on real-world FMCG sales reporting and analytical responsibilities previously performed by the author. All company names, customer/distributor names, products, transactions, targets, inventory records, collection records, and financial figures in this workbook are synthetic and illustrative. The workbook does not reproduce or disclose confidential employer data.

Sheet 03_Cities
A1: City ID | B1: City | C1: Region | D1: Status
A2: C001 | B2: Karachi | C2: Sindh | D2: Active
A3: C002 | B3: Lahore | C3: Punjab | D3: Active
A4: C003 | B4: Islamabad | C4: Federal | D4: Active
A5: C004 | B5: Rawalpindi | C5: Punjab | D5: Active

Sheet 04_Sales_Team
A1: RSM ID | B1: RSM Name | C1: Salesperson ID | D1: Salesperson Name | E1: City ID
A2: R001 | B2: Ali Khan | C2: SP001 | D2: Ahmed Raza | E2: C001
A3: R001 | B3: Ali Khan | C3: SP002 | D3: Bilal Ahmed | E3: C001
A4: R001 | B4: Ali Khan | C4: SP003 | D4: Farhan Malik | E4: C001
A5: R002 | B5: Hamza Malik | C5: SP004 | D5: Danish Ali | E5: C002
A6: R002 | B6: Hamza Malik | C6: SP005 | D6: Usman Tariq | E6: C002
A7: R002 | B7: Hamza Malik | C7: SP006 | D7: Saad Ahmed | E7: C002
A8: R003 | B8: Imran Shah | C8: SP007 | D8: Hassan Raza | E8: C003
A9: R003 | B9: Imran Shah | C9: SP008 | D9: Kamran Ali | E9: C003
A10: R003 | B10: Imran Shah | C10: SP009 | D10: Salman Ahmed | E10: C003
A11: R004 | B11: Fahad Khan | C11: SP010 | D11: Adeel Hussain | E11: C004
A12: R004 | B12: Fahad Khan | C12: SP011 | D12: Rizwan Ali | E12: C004
A13: R004 | B13: Fahad Khan | C13: SP012 | D13: Naveed Ahmed | E13: C004

Sheet 05_Distributors
A1: Distributor ID | B1: Distributor Name | C1: City ID | D1: RSM ID | E1: Salesperson ID | F1: Status
A2: D001 | B2: Karachi Distributors | C2: C001 | D2: R001 | E2: SP001 | F2: Active
A3: D002 | B3: Metro Wholesale Karachi | C3: C001 | D3: R001 | E3: SP002 | F3: Active
A4: D003 | B4: Sindh Trade Network | C4: C001 | D4: R001 | E4: SP003 | F4: Active
A5: D004 | B5: Lahore Trading Co. | C5: C002 | D5: R002 | E5: SP004 | F5: Active
A6: D005 | B6: Punjab Distribution House | C6: C002 | D6: R002 | E6: SP005 | F6: Active
A7: D006 | B7: Lahore Wholesale Mart | C7: C002 | D7: R002 | E7: SP006 | F7: Active
A8: D007 | B8: Capital Distribution Co. | C8: C003 | D8: R003 | E8: SP007 | F8: Active
A9: D008 | B9: Islamabad Trade Link | C9: C003 | D9: R003 | E9: SP008 | F9: Active
A10: D009 | B10: Capital Wholesale Network | C10: C003 | D10: R003 | E10: SP009 | F10: Active
A11: D010 | B11: Rawalpindi Distribution Co. | C11: C004 | D11: R004 | E11: SP010 | F11: Active
A12: D011 | B12: Potohar Trade House | C12: C004 | D12: R004 | E12: SP011 | F12: Active
A13: D012 | B13: Rawalpindi Wholesale Mart | C13: C004 | D13: R004 | E13: SP012 | F13: Active

Sheet 06_Products
A1: Product ID | B1: Brand | C1: Product Name | D1: Category | E1: Sub-Category | F1: Pack Size | G1: Unit
A2: P001 | B2: Morning Harvest | C2: Corn Flakes Original | D2: Morning Cereals | E2: Corn Flakes | F2: 250g | G2: Box
A3: P002 | B3: Morning Harvest | C3: Corn Flakes Original | D3: Morning Cereals | E3: Corn Flakes | F3: 500g | G3: Box
A4: P003 | B4: Morning Harvest | C4: Corn Flakes Original | D4: Morning Cereals | E4: Corn Flakes | F4: 1kg | G4: Box
A5: P004 | B5: Morning Harvest | C5: Honey Corn Flakes | D5: Morning Cereals | E5: Corn Flakes | F5: 250g | G5: Box
A6: P005 | B6: Morning Harvest | C6: Honey Corn Flakes | D6: Morning Cereals | E6: Corn Flakes | F6: 500g | G6: Box
A7: P006 | B7: Morning Harvest | C7: Chocolate Corn Flakes | D7: Morning Cereals | E7: Corn Flakes | F7: 250g | G7: Box
A8: P007 | B8: Morning Harvest | C8: Chocolate Corn Flakes | D8: Morning Cereals | E8: Corn Flakes | F8: 500g | G8: Box
A9: P008 | B9: Morning Harvest | C9: Frosted Flakes | D9: Morning Cereals | E9: Flakes | F9: 250g | G9: Box
A10: P009 | B10: Morning Harvest | C10: Frosted Flakes | D10: Morning Cereals | E10: Flakes | F10: 500g | G10: Box
A11: P010 | B11: Morning Harvest | C11: Bran Flakes | D11: Morning Cereals | E11: Healthy Cereals | F11: 250g | G11: Box
A12: P011 | B12: Morning Harvest | C12: Bran Flakes | D12: Morning Cereals | E12: Healthy Cereals | F12: 500g | G12: Box
... A57: P056 | B57: Melegatti | C57: Filled Croissant Vanilla | D57: Cakes & Croissants | E57: Croissants | F57: 6 Pack | G57: Pack

Sheet 07_Calendar
A1: Date | B1: Year | C1: Month No | D1: Month | E1: Quarter | F1: Week No | G1: Week Start | H1: Week End | I1: Day | J1: Day No | K1: Month-Year
A2: =DATE(2026,1,1) -> 46023 | B2: =YEAR(A2) -> 2026 | C2: =MONTH(A2) -> 1 | D2: =TEXT(A2,"mmmm") -> January | E2: ="Q"&ROUNDUP(MONTH(A2)/3,0) -> Q1 | F2: =WEEKNUM(A2,2) -> 1 | G2: =A2-WEEKDAY(A2,2)+1 -> 46020 | H2: =G2+6 -> 46026 | I2: =TEXT(A2,"dddd") -> Thursday | J2: =WEEKDAY(A2,2) -> 4 | K2: =TEXT(A2,"mmm-yyyy") -> Jan-2026
A3: =A2+1 -> 46024 | B3: =YEAR(A3) -> 2026 | C3: =MONTH(A3) -> 1 | D3: =TEXT(A3,"mmmm") -> January | E3: ="Q"&ROUNDUP(MONTH(A3)/3,0) -> Q1 | F3: =WEEKNUM(A3,2) -> 1 | G3: =A3-WEEKDAY(A3,2)+1 -> 46020 | H3: =G3+6 -> 46026 | I3: =TEXT(A3,"dddd") -> Friday | J3: =WEEKDAY(A3,2) -> 5 | K3: =TEXT(A3,"mmm-yyyy") -> Jan-2026
A4: =A3+1 -> 46025 | B4: =YEAR(A4) -> 2026 | C4: =MONTH(A4) -> 1 | D4: =TEXT(A4,"mmmm") -> January | E4: ="Q"&ROUNDUP(MONTH(A4)/3,0) -> Q1 | F4: =WEEKNUM(A4,2) -> 1 | G4: =A4-WEEKDAY(A4,2)+1 -> 46020 | H4: =G4+6 -> 46026 | I4: =TEXT(A4,"dddd") -> Saturday | J4: =WEEKDAY(A4,2) -> 6 | K4: =TEXT(A4,"mmm-yyyy") -> Jan-2026
A5: =A4+1 -> 46026 | B5: =YEAR(A5) -> 2026 | C5: =MONTH(A5) -> 1 | D5: =TEXT(A5,"mmmm") -> January | E5: ="Q"&ROUNDUP(MONTH(A5)/3,0) -> Q1 | F5: =WEEKNUM(A5,2) -> 1 | G5: =A5-WEEKDAY(A5,2)+1 -> 46020 | H5: =G5+6 -> 46026 | I5: =TEXT(A5,"dddd") -> Sunday | J5: =WEEKDAY(A5,2) -> 7 | K5: =TEXT(A5,"mmm-yyyy") -> Jan-2026
A6: =A5+1 -> 46027 | B6: =YEAR(A6) -> 2026 | C6: =MONTH(A6) -> 1 | D6: =TEXT(A6,"mmmm") -> January | E6: ="Q"&ROUNDUP(MONTH(A6)/3,0) -> Q1 | F6: =WEEKNUM(A6,2) -> 2 | G6: =A6-WEEKDAY(A6,2)+1 -> 46027 | H6: =G6+6 -> 46033 | I6: =TEXT(A6,"dddd") -> Monday | J6: =WEEKDAY(A6,2) -> 1 | K6: =TEXT(A6,"mmm-yyyy") -> Jan-2026
A7: =A6+1 -> 46028 | B7: =YEAR(A7) -> 2026 | C7: =MONTH(A7) -> 1 | D7: =TEXT(A7,"mmmm") -> January | E7: ="Q"&ROUNDUP(MONTH(A7)/3,0) -> Q1 | F7: =WEEKNUM(A7,2) -> 2 | G7: =A7-WEEKDAY(A7,2)+1 -> 46027 | H7: =G7+6 -> 46033 | I7: =TEXT(A7,"dddd") -> Tuesday | J7: =WEEKDAY(A7,2) -> 2 | K7: =TEXT(A7,"mmm-yyyy") -> Jan-2026
A8: =A7+1 -> 46029 | B8: =YEAR(A8) -> 2026 | C8: =MONTH(A8) -> 1 | D8: =TEXT(A8,"mmmm") -> January | E8: ="Q"&ROUNDUP(MONTH(A8)/3,0) -> Q1 | F8: =WEEKNUM(A8,2) -> 2 | G8: =A8-WEEKDAY(A8,2)+1 -> 46027 | H8: =G8+6 -> 46033 | I8: =TEXT(A8,"dddd") -> Wednesday | J8: =WEEKDAY(A8,2) -> 3 | K8: =TEXT(A8,"mmm-yyyy") -> Jan-2026
A9: =A8+1 -> 46030 | B9: =YEAR(A9) -> 2026 | C9: =MONTH(A9) -> 1 | D9: =TEXT(A9,"mmmm") -> January | E9: ="Q"&ROUNDUP(MONTH(A9)/3,0) -> Q1 | F9: =WEEKNUM(A9,2) -> 2 | G9: =A9-WEEKDAY(A9,2)+1 -> 46027 | H9: =G9+6 -> 46033 | I9: =TEXT(A9,"dddd") -> Thursday | J9: =WEEKDAY(A9,2) -> 4 | K9: =TEXT(A9,"mmm-yyyy") -> Jan-2026
A10: =A9+1 -> 46031 | B10: =YEAR(A10) -> 2026 | C10: =MONTH(A10) -> 1 | D10: =TEXT(A10,"mmmm") -> January | E10: ="Q"&ROUNDUP(MONTH(A10)/3,0) -> Q1 | F10: =WEEKNUM(A10,2) -> 2 | G10: =A10-WEEKDAY(A10,2)+1 -> 46027 | H10: =G10+6 -> 46033 | I10: =TEXT(A10,"dddd") -> Friday | J10: =WEEKDAY(A10,2) -> 5 | K10: =TEXT(A10,"mmm-yyyy") -> Jan-2026
A11: =A10+1 -> 46032 | B11: =YEAR(A11) -> 2026 | C11: =MONTH(A11) -> 1 | D11: =TEXT(A11,"mmmm") -> January | E11: ="Q"&ROUNDUP(MONTH(A11)/3,0) -> Q1 | F11: =WEEKNUM(A11,2) -> 2 | G11: =A11-WEEKDAY(A11,2)+1 -> 46027 | H11: =G11+6 -> 46033 | I11: =TEXT(A11,"dddd") -> Saturday | J11: =WEEKDAY(A11,2) -> 6 | K11: =TEXT(A11,"mmm-yyyy") -> Jan-2026
A12: =A11+1 -> 46033 | B12: =YEAR(A12) -> 2026 | C12: =MONTH(A12) -> 1 | D12: =TEXT(A12,"mmmm") -> January | E12: ="Q"&ROUNDUP(MONTH(A12)/3,0) -> Q1 | F12: =WEEKNUM(A12,2) -> 2 | G12: =A12-WEEKDAY(A12,2)+1 -> 46027 | H12: =G12+6 -> 46033 | I12: =TEXT(A12,"dddd") -> Sunday | J12: =WEEKDAY(A12,2) -> 7 | K12: =TEXT(A12,"mmm-yyyy") -> Jan-2026
A13: =A12+1 -> 46034 | B13: =YEAR(A13) -> 2026 | C13: =MONTH(A13) -> 1 | D13: =TEXT(A13,"mmmm") -> January | E13: ="Q"&ROUNDUP(MONTH(A13)/3,0) -> Q1 | F13: =WEEKNUM(A13,2) -> 3 | G13: =A13-WEEKDAY(A13,2)+1 -> 46034 | H13: =G13+6 -> 46040 | I13: =TEXT(A13,"dddd") -> Monday | J13: =WEEKDAY(A13,2) -> 1 | K13: =TEXT(A13,"mmm-yyyy") -> Jan-2026
A14: =A13+1 -> 46035 | B14: =YEAR(A14) -> 2026 | C14: =MONTH(A14) -> 1 | D14: =TEXT(A14,"mmmm") -> January | E14: ="Q"&ROUNDUP(MONTH(A14)/3,0) -> Q1 | F14: =WEEKNUM(A14,2) -> 3 | G14: =A14-WEEKDAY(A14,2)+1 -> 46034 | H14: =G14+6 -> 46040 | I14: =TEXT(A14,"dddd") -> Tuesday | J14: =WEEKDAY(A14,2) -> 2 | K14: =TEXT(A14,"mmm-yyyy") -> Jan-2026
... A366: =A365+1 -> 46387 | B366: =YEAR(A366) -> 2026 | C366: =MONTH(A366) -> 12 | D366: =TEXT(A366,"mmmm") -> December | E366: ="Q"&ROUNDUP(MONTH(A366)/3,0) -> Q4 | F366: =WEEKNUM(A366,2) -> 53 | G366: =A366-WEEKDAY(A366,2)+1 -> 46384 | H366: =G366+6 -> 46390 | I366: =TEXT(A366,"dddd") -> Thursday | J366: =WEEKDAY(A366,2) -> 4 | K366: =TEXT(A366,"mmm-yyyy") -> Dec-2026

Sheet 08_Sales_Targets
A1: MonthYear | B1: Month No | C1: Salesperson ID | D1: RSM ID | E1: City ID | F1: Target Amount
A2: 46023 | B2: 1 | C2: SP001 | D2: R001 | E2: C001 | F2: 2500000
A3: 46023 | B3: 1 | C3: SP002 | D3: R001 | E3: C001 | F3: 2300000
A4: 46023 | B4: 1 | C4: SP003 | D4: R001 | E4: C001 | F4: 2200000
A5: 46023 | B5: 1 | C5: SP004 | D5: R002 | E5: C002 | F5: 2700000
A6: 46023 | B6: 1 | C6: SP005 | D6: R002 | E6: C002 | F6: 2500000
A7: 46023 | B7: 1 | C7: SP006 | D7: R002 | E7: C002 | F7: 2300000
A8: 46023 | B8: 1 | C8: SP007 | D8: R003 | E8: C003 | F8: 2400000
A9: 46023 | B9: 1 | C9: SP008 | D9: R003 | E9: C003 | F9: 2200000
A10: 46023 | B10: 1 | C10: SP009 | D10: R003 | E10: C003 | F10: 2100000
A11: 46023 | B11: 1 | C11: SP010 | D11: R004 | E11: C004 | F11: 2200000
A12: 46023 | B12: 1 | C12: SP011 | D12: R004 | E12: C004 | F12: 2000000
A13: 46023 | B13: 1 | C13: SP012 | D13: R004 | E13: C004 | F13: 1900000
... A145: 46357 | B145: 12 | C145: SP012 | D145: R004 | E145: C004 | F145: 2280000
F146: =SUBTOTAL(109,tblSalesTargets[Target Amount]) -> 348075000

Sheet 09_Sales_Transactions
A1: Transaction ID | B1: Date | C1: Distributor ID | D1: Salesperson ID | E1: RSM ID | F1: City ID | G1: Product ID | H1: Quantity | I1: Unit Price | J1: Sales Amount
A2: TXN0001 | B2: 46027 | C2: D001 | D2: SP001 | E2: R001 | F2: C001 | G2: P001 | H2: 120 | I2: 850 | J2: =H2*I2 -> 102000
A3: TXN0002 | B3: 46029 | C3: D002 | D3: SP002 | E3: R001 | F3: C001 | G3: P004 | H3: 150 | I3: 900 | J3: =H3*I3 -> 135000
A4: TXN0003 | B4: 46031 | C4: D003 | D4: SP003 | E4: R001 | F4: C001 | G4: P014 | H4: 80 | I4: 1450 | J4: =H4*I4 -> 116000
A5: TXN0004 | B5: 46028 | C5: D004 | D5: SP004 | E5: R002 | F5: C002 | G5: P032 | H5: 100 | I5: 2200 | J5: =H5*I5 -> 220000
A6: TXN0005 | B6: 46032 | C6: D005 | D6: SP005 | E6: R002 | F6: C002 | G6: P035 | H6: 90 | I6: 2400 | J6: =H6*I6 -> 216000
A7: TXN0006 | B7: 46036 | C7: D006 | D7: SP006 | E7: R002 | F7: C002 | G7: P041 | H7: 130 | I7: 1250 | J7: =H7*I7 -> 162500
A8: TXN0007 | B8: 46030 | C8: D007 | D8: SP007 | E8: R003 | F8: C003 | G8: P002 | H8: 140 | I8: 1450 | J8: =H8*I8 -> 203000
A9: TXN0008 | B9: 46034 | C9: D008 | D9: SP008 | E9: R003 | F9: C003 | G9: P015 | H9: 75 | I9: 2600 | J9: =H9*I9 -> 195000
A10: TXN0009 | B10: 46040 | C10: D009 | D10: SP009 | E10: R003 | F10: C003 | G10: P049 | H10: 160 | I10: 1100 | J10: =H10*I10 -> 176000
A11: TXN0010 | B11: 46033 | C11: D010 | D11: SP010 | E11: R004 | F11: C004 | G11: P005 | H11: 130 | I11: 950 | J11: =H11*I11 -> 123500
A12: TXN0011 | B12: 46038 | C12: D011 | D12: SP011 | E12: R004 | F12: C004 | G12: P043 | H12: 100 | I12: 1200 | J12: =H12*I12 -> 120000
A13: TXN0012 | B13: 46043 | C13: D012 | D13: SP012 | E13: R004 | F13: C004 | G13: P051 | H13: 150 | I13: 1150 | J13: =H13*I13 -> 172500
... A301: TXN0300 | B301: 46378 | C301: D012 | D301: SP012 | E301: R004 | F301: C004 | G301: P056 | H301: 165 | I301: 1350 | J301: =H301*I301 -> 222750
J302: =SUBTOTAL(109,tblSalesTransactions[Sales Amount]) -> 60255750

Sheet 10_Inventory
A1: Snapshot Date | B1: Distributor ID | C1: Product ID | D1: Opening Stock Qty | E1: Closing Stock Qty | F1: Stock Value | G1: Stock Status
A2: 46112 | B2: D001 | C2: P001 | D2: 180 | E2: 145 | F2: 123250 | G2: Normal
A3: 46112 | B3: D001 | C3: P014 | D3: 120 | E3: 92 | F3: 133400 | G3: Normal
A4: 46112 | B4: D001 | C4: P032 | D4: 75 | E4: 58 | F4: 127600 | G4: Normal
A5: 46112 | B5: D001 | C5: P041 | D5: 90 | E5: 74 | F5: 92500 | G5: Normal
A6: 46112 | B6: D002 | C6: P004 | D6: 160 | E6: 128 | F6: 115200 | G6: Normal
A7: 46112 | B7: D002 | C7: P015 | D7: 105 | E7: 82 | F7: 213200 | G7: Normal
A8: 46112 | B8: D002 | C8: P035 | D8: 70 | E8: 61 | F8: 146400 | G8: Normal
A9: 46112 | B9: D002 | C9: P049 | D9: 130 | E9: 98 | F9: 107800 | G9: Normal
A10: 46112 | B10: D003 | C10: P006 | D10: 145 | E10: 118 | F10: 135700 | G10: Normal
A11: 46112 | B11: D003 | C11: P020 | D11: 95 | E11: 76 | F11: 136800 | G11: Normal
A12: 46112 | B12: D003 | C12: P038 | D12: 65 | E12: 51 | F12: 147900 | G12: Normal
A13: 46112 | B13: D003 | C13: P051 | D13: 110 | E13: 87 | F13: 100050 | G13: Normal
... A193: 46387 | B193: D012 | C193: P054 | D193: 47 | E193: 36 | F193: 37800 | G193: Normal

Sheet 11_Collections
A1: Collection ID | B1: Invoice Date | C1: Distributor ID | D1: Salesperson ID | E1: RSM ID | F1: City ID | G1: Invoice Amount | H1: Due Date | I1: Collection Date | J1: Collected Amount | K1: Outstanding Amount | L1: Collection Status
A2: COL001 | B2: 46027 | C2: D001 | D2: SP001 | E2: R001 | F2: C001 | G2: 85000 | H2: 46057 | I2: 46055 | J2: 85000 | K2: =G2-J2 -> 0 | L2: =IF(K2=0,"Paid",IF(J2=0,"Outstanding","Partial")) -> Paid
A3: COL002 | B3: 46030 | C3: D002 | D3: SP002 | E3: R001 | F3: C001 | G3: 92000 | H3: 46060 | I3: 46058 | J3: 92000 | K3: =G3-J3 -> 0 | L3: =IF(K3=0,"Paid",IF(J3=0,"Outstanding","Partial")) -> Paid
A4: COL003 | B4: 46034 | C4: D003 | D4: SP003 | E4: R001 | F4: C001 | G4: 78000 | H4: 46064 | I4: 46063 | J4: 60000 | K4: =G4-J4 -> 18000 | L4: =IF(K4=0,"Paid",IF(J4=0,"Outstanding","Partial")) -> Partial
A5: COL004 | B5: 46037 | C5: D004 | D5: SP004 | E5: R002 | F5: C002 | G5: 105000 | H5: 46067 | I5: 46067 | J5: 105000 | K5: =G5-J5 -> 0 | L5: =IF(K5=0,"Paid",IF(J5=0,"Outstanding","Partial")) -> Paid
A6: COL005 | B6: 46042 | C6: D005 | D6: SP005 | E6: R002 | F6: C002 | G6: 115000 | H6: 46072 | I6: 46071 | J6: 115000 | K6: =G6-J6 -> 0 | L6: =IF(K6=0,"Paid",IF(J6=0,"Outstanding","Partial")) -> Paid
A7: COL006 | B7: 46046 | C7: D006 | D7: SP006 | E7: R002 | F7: C002 | G7: 88000 | H7: 46076 | J7: 0 | K7: =G7-J7 -> 88000 | L7: =IF(K7=0,"Paid",IF(J7=0,"Outstanding","Partial")) -> Outstanding
A8: COL007 | B8: 46050 | C8: D007 | D8: SP007 | E8: R003 | F8: C003 | G8: 97000 | H8: 46080 | I8: 46078 | J8: 97000 | K8: =G8-J8 -> 0 | L8: =IF(K8=0,"Paid",IF(J8=0,"Outstanding","Partial")) -> Paid
A9: COL008 | B9: 46056 | C9: D008 | D9: SP008 | E9: R003 | F9: C003 | G9: 112000 | H9: 46086 | I9: 46084 | J9: 80000 | K9: =G9-J9 -> 32000 | L9: =IF(K9=0,"Paid",IF(J9=0,"Outstanding","Partial")) -> Partial
A10: COL009 | B10: 46060 | C10: D009 | D10: SP009 | E10: R003 | F10: C003 | G10: 89000 | H10: 46090 | I10: 46090 | J10: 89000 | K10: =G10-J10 -> 0 | L10: =IF(K10=0,"Paid",IF(J10=0,"Outstanding","Partial")) -> Paid
A11: COL010 | B11: 46064 | C11: D010 | D11: SP010 | E11: R004 | F11: C004 | G11: 125000 | H11: 46093 | I11: 46091 | J11: 125000 | K11: =G11-J11 -> 0 | L11: =IF(K11=0,"Paid",IF(J11=0,"Outstanding","Partial")) -> Paid
A12: COL011 | B12: 46068 | C12: D011 | D12: SP011 | E12: R004 | F12: C004 | G12: 76000 | H12: 46097 | J12: 0 | K12: =G12-J12 -> 76000 | L12: =IF(K12=0,"Paid",IF(J12=0,"Outstanding","Partial")) -> Outstanding
A13: COL012 | B13: 46073 | C13: D012 | D13: SP012 | E13: R004 | F13: C004 | G13: 108000 | H13: 46102 | I13: 46101 | J13: 90000 | K13: =G13-J13 -> 18000 | L13: =IF(K13=0,"Paid",IF(J13=0,"Outstanding","Partial")) -> Partial
A14: COL013 | B14: 46086 | C14: D001 | D14: SP001 | E14: R001 | F14: C001 | G14: 95000 | H14: 46116 | I14: 46114 | J14: 95000 | K14: =G14-J14 -> 0 | L14: =IF(K14=0,"Paid",IF(J14=0,"Outstanding","Partial")) -> Paid
A15: COL014 | B15: 46091 | C15: D002 | D15: SP002 | E15: R001 | F15: C001 | G15: 118000 | H15: 46121 | I15: 46120 | J15: 118000 | K15: =G15-J15 -> 0 | L15: =IF(K15=0,"Paid",IF(J15=0,"Outstanding","Partial")) -> Paid
A16: COL015 | B16: 46096 | C16: D003 | D16: SP003 | E16: R001 | F16: C001 | G16: 82000 | H16: 46126 | J16: 0 | K16: =G16-J16 -> 82000 | L16: =IF(K16=0,"Paid",IF(J16=0,"Outstanding","Partial")) -> Outstanding
A17: COL016 | B17: 46101 | C17: D004 | D17: SP004 | E17: R002 | F17: C002 | G17: 110000 | H17: 46131 | I17: 46129 | J17: 70000 | K17: =G17-J17 -> 40000 | L17: =IF(K17=0,"Paid",IF(J17=0,"Outstanding","Partial")) -> Partial
A18: COL017 | B18: 46106 | C18: D005 | D18: SP005 | E18: R002 | F18: C002 | G18: 125000 | H18: 46136 | I18: 46136 | J18: 125000 | K18: =G18-J18 -> 0 | L18: =IF(K18=0,"Paid",IF(J18=0,"Outstanding","Partial")) -> Paid
A19: COL018 | B19: 46109 | C19: D006 | D19: SP006 | E19: R002 | F19: C002 | G19: 93000 | H19: 46139 | I19: 46138 | J19: 93000 | K19: =G19-J19 -> 0 | L19: =IF(K19=0,"Paid",IF(J19=0,"Outstanding","Partial")) -> Paid
A20: COL019 | B20: 46114 | C20: D007 | D20: SP007 | E20: R003 | F20: C003 | G20: 102000 | H20: 46144 | I20: 46142 | J20: 102000 | K20: =G20-J20 -> 0 | L20: =IF(K20=0,"Paid",IF(J20=0,"Outstanding","Partial")) -> Paid
A21: COL020 | B21: 46120 | C21: D008 | D21: SP008 | E21: R003 | F21: C003 | G21: 120000 | H21: 46150 | J21: 0 | K21: =G21-J21 -> 120000 | L21: =IF(K21=0,"Paid",IF(J21=0,"Outstanding","Partial")) -> Outstanding
A22: COL021 | B22: 46126 | C22: D009 | D22: SP009 | E22: R003 | F22: C003 | G22: 94000 | H22: 46156 | I22: 46154 | J22: 94000 | K22: =G22-J22 -> 0 | L22: =IF(K22=0,"Paid",IF(J22=0,"Outstanding","Partial")) -> Paid
A23: COL022 | B23: 46132 | C23: D010 | D23: SP010 | E23: R004 | F23: C004 | G23: 135000 | H23: 46162 | I23: 46161 | J23: 135000 | K23: =G23-J23 -> 0 | L23: =IF(K23=0,"Paid",IF(J23=0,"Outstanding","Partial")) -> Paid
A24: COL023 | B24: 46137 | C24: D011 | D24: SP011 | E24: R004 | F24: C004 | G24: 84000 | H24: 46167 | J24: 0 | K24: =G24-J24 -> 84000 | L24: =IF(K24=0,"Paid",IF(J24=0,"Outstanding","Partial")) -> Outstanding
A25: COL024 | B25: 46140 | C25: D012 | D25: SP012 | E25: R004 | F25: C004 | G25: 115000 | H25: 46170 | I25: 46169 | J25: 100000 | K25: =G25-J25 -> 15000 | L25: =IF(K25=0,"Paid",IF(J25=0,"Outstanding","Partial")) -> Partial
A26: COL025 | B26: 46147 | C26: D001 | D26: SP001 | E26: R001 | F26: C001 | G26: 108000 | H26: 46177 | I26: 46176 | J26: 108000 | K26: =G26-J26 -> 0 | L26: =IF(K26=0,"Paid",IF(J26=0,"Outstanding","Partial")) -> Paid
A27: COL026 | B27: 46152 | C27: D002 | D27: SP002 | E27: R001 | F27: C001 | G27: 125000 | H27: 46182 | I27: 46181 | J27: 125000 | K27: =G27-J27 -> 0 | L27: =IF(K27=0,"Paid",IF(J27=0,"Outstanding","Partial")) -> Paid
A28: COL027 | B28: 46157 | C28: D003 | D28: SP003 | E28: R001 | F28: C001 | G28: 90000 | H28: 46187 | J28: 0 | K28: =G28-J28 -> 90000 | L28: =IF(K28=0,"Paid",IF(J28=0,"Outstanding","Partial")) -> Outstanding
A29: COL028 | B29: 46162 | C29: D004 | D29: SP004 | E29: R002 | F29: C002 | G29: 118000 | H29: 46192 | I29: 46191 | J29: 90000 | K29: =G29-J29 -> 28000 | L29: =IF(K29=0,"Paid",IF(J29=0,"Outstanding","Partial")) -> Partial
A30: COL029 | B30: 46167 | C30: D005 | D30: SP005 | E30: R002 | F30: C002 | G30: 132000 | H30: 46197 | I30: 46197 | J30: 132000 | K30: =G30-J30 -> 0 | L30: =IF(K30=0,"Paid",IF(J30=0,"Outstanding","Partial")) -> Paid
A31: COL030 | B31: 46170 | C31: D006 | D31: SP006 | E31: R002 | F31: C002 | G31: 98000 | H31: 46200 | I31: 46199 | J31: 98000 | K31: =G31-J31 -> 0 | L31: =IF(K31=0,"Paid",IF(J31=0,"Outstanding","Partial")) -> Paid
A32: COL031 | B32: 46176 | C32: D007 | D32: SP007 | E32: R003 | F32: C003 | G32: 110000 | H32: 46206 | I32: 46205 | J32: 110000 | K32: =G32-J32 -> 0 | L32: =IF(K32=0,"Paid",IF(J32=0,"Outstanding","Partial")) -> Paid
A33: COL032 | B33: 46181 | C33: D008 | D33: SP008 | E33: R003 | F33: C003 | G33: 128000 | H33: 46211 | J33: 0 | K33: =G33-J33 -> 128000 | L33: =IF(K33=0,"Paid",IF(J33=0,"Outstanding","Partial")) -> Outstanding
A34: COL033 | B34: 46187 | C34: D009 | D34: SP009 | E34: R003 | F34: C003 | G34: 99000 | H34: 46217 | I34: 46215 | J34: 99000 | K34: =G34-J34 -> 0 | L34: =IF(K34=0,"Paid",IF(J34=0,"Outstanding","Partial")) -> Paid
A35: COL034 | B35: 46193 | C35: D010 | D35: SP010 | E35: R004 | F35: C004 | G35: 142000 | H35: 46223 | I35: 46221 | J35: 142000 | K35: =G35-J35 -> 0 | L35: =IF(K35=0,"Paid",IF(J35=0,"Outstanding","Partial")) -> Paid
A36: COL035 | B36: 46198 | C36: D011 | D36: SP011 | E36: R004 | F36: C004 | G36: 91000 | H36: 46228 | J36: 0 | K36: =G36-J36 -> 91000 | L36: =IF(K36=0,"Paid",IF(J36=0,"Outstanding","Partial")) -> Outstanding
A37: COL036 | B37: 46201 | C37: D012 | D37: SP012 | E37: R004 | F37: C004 | G37: 122000 | H37: 46231 | I37: 46230 | J37: 100000 | K37: =G37-J37 -> 22000 | L37: =IF(K37=0,"Paid",IF(J37=0,"Outstanding","Partial")) -> Partial
A38: COL037 | B38: 46208 | C38: D001 | D38: SP001 | E38: R001 | F38: C001 | G38: 115000 | H38: 46238 | I38: 46236 | J38: 115000 | K38: =G38-J38 -> 0 | L38: =IF(K38=0,"Paid",IF(J38=0,"Outstanding","Partial")) -> Paid
A39: COL038 | B39: 46213 | C39: D002 | D39: SP002 | E39: R001 | F39: C001 | G39: 132000 | H39: 46243 | I39: 46242 | J39: 132000 | K39: =G39-J39 -> 0 | L39: =IF(K39=0,"Paid",IF(J39=0,"Outstanding","Partial")) -> Paid
A40: COL039 | B40: 46218 | C40: D003 | D40: SP003 | E40: R001 | F40: C001 | G40: 96000 | H40: 46248 | J40: 0 | K40: =G40-J40 -> 96000 | L40: =IF(K40=0,"Paid",IF(J40=0,"Outstanding","Partial")) -> Outstanding
...

Sheet 12_Performance_Calculations
A1: MonthYear | B1: Month No | C1: Salesperson ID | D1: RSM ID | E1: City ID | F1: Target Amount | G1: Actual Sales | H1: SALES VARIANCE | I1: Achievement % | J1: Performance Status
A2: =DATE(2026,B2,1) -> 46023 | B2: =ROUNDUP(ROWS($B$2:B2)/12,0) -> 1 | C2: ="SP"&TEXT(MOD(ROWS($C$2:C2)-1,12)+1,"000") -> SP001 | D2: R001 | E2: C001 | F2: =SUMIFS(tblSalesTargets[Target Amount],tblSalesTargets[MonthYear],A2,tblSalesTargets[Salesperson ID],C2) -> 2500000 | G2: =SUMIFS(tblSalesTransactions[Sales Amount],tblSalesTransactions[Salesperson ID],C2,tblSalesTransactions[Date],">="&DATE(YEAR(A2),MONTH(A2),1),tblSalesTransactions[Date],"<"&EDATE(A2,1)) -> 350500 | H2: =G2-F2 -> -2149500 | I2: =IFERROR(G2/F2,0) -> 0.1402 | J2: =IF(I2>='02_Control_Panel'!$B$8,"Achieved",IF(I2>='02_Control_Panel'!$B$7,"Near Target","Below Target")) -> Below Target
A3: =DATE(2026,B3,1) -> 46023 | B3: =ROUNDUP(ROWS($B$2:B3)/12,0) -> 1 | C3: ="SP"&TEXT(MOD(ROWS($C$2:C3)-1,12)+1,"000") -> SP002 | D3: R001 | E3: C001 | F3: =SUMIFS(tblSalesTargets[Target Amount],tblSalesTargets[MonthYear],A3,tblSalesTargets[Salesperson ID],C3) -> 2300000 | G3: =SUMIFS(tblSalesTransactions[Sales Amount],tblSalesTransactions[Salesperson ID],C3,tblSalesTransactions[Date],">="&DATE(YEAR(A3),MONTH(A3),1),tblSalesTransactions[Date],"<"&EDATE(A3,1)) -> 375000 | H3: =G3-F3 -> -1925000 | I3: =IFERROR(G3/F3,0) -> 0.16304348 | J3: =IF(I3>='02_Control_Panel'!$B$8,"Achieved",IF(I3>='02_Control_Panel'!$B$7,"Near Target","Below Target")) -> Below Target
A4: =DATE(2026,B4,1) -> 46023 | B4: =ROUNDUP(ROWS($B$2:B4)/12,0) -> 1 | C4: ="SP"&TEXT(MOD(ROWS($C$2:C4)-1,12)+1,"000") -> SP003 | D4: R001 | E4: C001 | F4: =SUMIFS(tblSalesTargets[Target Amount],tblSalesTargets[MonthYear],A4,tblSalesTargets[Salesperson ID],C4) -> 2200000 | G4: =SUMIFS(tblSalesTransactions[Sales Amount],tblSalesTransactions[Salesperson ID],C4,tblSalesTransactions[Date],">="&DATE(YEAR(A4),MONTH(A4),1),tblSalesTransactions[Date],"<"&EDATE(A4,1)) -> 371750 | H4: =G4-F4 -> -1828250 | I4: =IFERROR(G4/F4,0) -> 0.16897727 | J4: =IF(I4>='02_Control_Panel'!$B$8,"Achieved",IF(I4>='02_Control_Panel'!$B$7,"Near Target","Below Target")) -> Below Target
A5: =DATE(2026,B5,1) -> 46023 | B5: =ROUNDUP(ROWS($B$2:B5)/12,0) -> 1 | C5: ="SP"&TEXT(MOD(ROWS($C$2:C5)-1,12)+1,"000") -> SP004 | D5: R002 | E5: C002 | F5: =SUMIFS(tblSalesTargets[Target Amount],tblSalesTargets[MonthYear],A5,tblSalesTargets[Salesperson ID],C5) -> 2700000 | G5: =SUMIFS(tblSalesTransactions[Sales Amount],tblSalesTransactions[Salesperson ID],C5,tblSalesTransactions[Date],">="&DATE(YEAR(A5),MONTH(A5),1),tblSalesTransactions[Date],"<"&EDATE(A5,1)) -> 648000 | H5: =G5-F5 -> -2052000 | I5: =IFERROR(G5/F5,0) -> 0.24 | J5: =IF(I5>='02_Control_Panel'!$B$8,"Achieved",IF(I5>='02_Control_Panel'!$B$7,"Near Target","Below Target")) -> Below Target
A6: =DATE(2026,B6,1) -> 46023 | B6: =ROUNDUP(ROWS($B$2:B6)/12,0) -> 1 | C6: ="SP"&TEXT(MOD(ROWS($C$2:C6)-1,12)+1,"000") -> SP005 | D6: R002 | E6: C002 | F6: =SUMIFS(tblSalesTargets[Target Amount],tblSalesTargets[MonthYear],A6,tblSalesTargets[Salesperson ID],C6) -> 2500000 | G6: =SUMIFS(tblSalesTransactions[Sales Amount],tblSalesTransactions[Salesperson ID],C6,tblSalesTransactions[Date],">="&DATE(YEAR(A6),MONTH(A6),1),tblSalesTransactions[Date],"<"&EDATE(A6,1)) -> 626000 | H6: =G6-F6 -> -1874000 | I6: =IFERROR(G6/F6,0) -> 0.2504 | J6: =IF(I6>='02_Control_Panel'!$B$8,"Achieved",IF(I6>='02_Control_Panel'!$B$7,"Near Target","Below Target")) -> Below Target
A7: =DATE(2026,B7,1) -> 46023 | B7: =ROUNDUP(ROWS($B$2:B7)/12,0) -> 1 | C7: ="SP"&TEXT(MOD(ROWS($C$2:C7)-1,12)+1,"000") -> SP006 | D7: R002 | E7: C002 | F7: =SUMIFS(tblSalesTargets[Target Amount],tblSalesTargets[MonthYear],A7,tblSalesTargets[Salesperson ID],C7) -> 2300000 | G7: =SUMIFS(tblSalesTransactions[Sales Amount],tblSalesTransactions[Salesperson ID],C7,tblSalesTransactions[Date],">="&DATE(YEAR(A7),MONTH(A7),1),tblSalesTransactions[Date],"<"&EDATE(A7,1)) -> 464500 | H7: =G7-F7 -> -1835500 | I7: =IFERROR(G7/F7,0) -> 0.20195652 | J7: =IF(I7>='02_Control_Panel'!$B$8,"Achieved",IF(I7>='02_Control_Panel'!$B$7,"Near Target","Below Target")) -> Below Target
A8: =DATE(2026,B8,1) -> 46023 | B8: =ROUNDUP(ROWS($B$2:B8)/12,0) -> 1 | C8: ="SP"&TEXT(MOD(ROWS($C$2:C8)-1,12)+1,"000") -> SP007 | D8: R003 | E8: C003 | F8: =SUMIFS(tblSalesTargets[Target Amount],tblSalesTargets[MonthYear],A8,tblSalesTargets[Salesperson ID],C8) -> 2400000 | G8: =SUMIFS(tblSalesTransactions[Sales Amount],tblSalesTransactions[Salesperson ID],C8,tblSalesTransactions[Date],">="&DATE(YEAR(A8),MONTH(A8),1),tblSalesTransactions[Date],"<"&EDATE(A8,1)) -> 638000 | H8: =G8-F8 -> -1762000 | I8: =IFERROR(G8/F8,0) -> 0.26583333 | J8: =IF(I8>='02_Control_Panel'!$B$8,"Achieved",IF(I8>='02_Control_Panel'!$B$7,"Near Target","Below Target")) -> Below Target
A9: =DATE(2026,B9,1) -> 46023 | B9: =ROUNDUP(ROWS($B$2:B9)/12,0) -> 1 | C9: ="SP"&TEXT(MOD(ROWS($C$2:C9)-1,12)+1,"000") -> SP008 | D9: R003 | E9: C003 | F9: =SUMIFS(tblSalesTargets[Target Amount],tblSalesTargets[MonthYear],A9,tblSalesTargets[Salesperson ID],C9) -> 2200000 | G9: =SUMIFS(tblSalesTransactions[Sales Amount],tblSalesTransactions[Salesperson ID],C9,tblSalesTransactions[Date],">="&DATE(YEAR(A9),MONTH(A9),1),tblSalesTransactions[Date],"<"&EDATE(A9,1)) -> 591000 | H9: =G9-F9 -> -1609000 | I9: =IFERROR(G9/F9,0) -> 0.26863636 | J9: =IF(I9>='02_Control_Panel'!$B$8,"Achieved",IF(I9>='02_Control_Panel'!$B$7,"Near Target","Below Target")) -> Below Target
A10: =DATE(2026,B10,1) -> 46023 | B10: =ROUNDUP(ROWS($B$2:B10)/12,0) -> 1 | C10: ="SP"&TEXT(MOD(ROWS($C$2:C10)-1,12)+1,"000") -> SP009 | D10: R003 | E10: C003 | F10: =SUMIFS(tblSalesTargets[Target Amount],tblSalesTargets[MonthYear],A10,tblSalesTargets[Salesperson ID],C10) -> 2100000 | G10: =SUMIFS(tblSalesTransactions[Sales Amount],tblSalesTransactions[Salesperson ID],C10,tblSalesTransactions[Date],">="&DATE(YEAR(A10),MONTH(A10),1),tblSalesTransactions[Date],"<"&EDATE(A10,1)) -> 456000 | H10: =G10-F10 -> -1644000 | I10: =IFERROR(G10/F10,0) -> 0.21714286 | J10: =IF(I10>='02_Control_Panel'!$B$8,"Achieved",IF(I10>='02_Control_Panel'!$B$7,"Near Target","Below Target")) -> Below Target
A11: =DATE(2026,B11,1) -> 46023 | B11: =ROUNDUP(ROWS($B$2:B11)/12,0) -> 1 | C11: ="SP"&TEXT(MOD(ROWS($C$2:C11)-1,12)+1,"000") -> SP010 | D11: R004 | E11: C004 | F11: =SUMIFS(tblSalesTargets[Target Amount],tblSalesTargets[MonthYear],A11,tblSalesTargets[Salesperson ID],C11) -> 2200000 | G11: =SUMIFS(tblSalesTransactions[Sales Amount],tblSalesTransactions[Salesperson ID],C11,tblSalesTransactions[Date],">="&DATE(YEAR(A11),MONTH(A11),1),tblSalesTransactions[Date],"<"&EDATE(A11,1)) -> 379500 | H11: =G11-F11 -> -1820500 | I11: =IFERROR(G11/F11,0) -> 0.1725 | J11: =IF(I11>='02_Control_Panel'!$B$8,"Achieved",IF(I11>='02_Control_Panel'!$B$7,"Near Target","Below Target")) -> Below Target
A12: =DATE(2026,B12,1) -> 46023 | B12: =ROUNDUP(ROWS($B$2:B12)/12,0) -> 1 | C12: ="SP"&TEXT(MOD(ROWS($C$2:C12)-1,12)+1,"000") -> SP011 | D12: R004 | E12: C004 | F12: =SUMIFS(tblSalesTargets[Target Amount],tblSalesTargets[MonthYear],A12,tblSalesTargets[Salesperson ID],C12) -> 2000000 | G12: =SUMIFS(tblSalesTransactions[Sales Amount],tblSalesTransactions[Salesperson ID],C12,tblSalesTransactions[Date],">="&DATE(YEAR(A12),MONTH(A12),1),tblSalesTransactions[Date],"<"&EDATE(A12,1)) -> 387000 | H12: =G12-F12 -> -1613000 | I12: =IFERROR(G12/F12,0) -> 0.1935 | J12: =IF(I12>='02_Control_Panel'!$B$8,"Achieved",IF(I12>='02_Control_Panel'!$B$7,"Near Target","Below Target")) -> Below Target
A13: =DATE(2026,B13,1) -> 46023 | B13: =ROUNDUP(ROWS($B$2:B13)/12,0) -> 1 | C13: ="SP"&TEXT(MOD(ROWS($C$2:C13)-1,12)+1,"000") -> SP012 | D13: R004 | E13: C004 | F13: =SUMIFS(tblSalesTargets[Target Amount],tblSalesTargets[MonthYear],A13,tblSalesTargets[Salesperson ID],C13) -> 1900000 | G13: =SUMIFS(tblSalesTransactions[Sales Amount],tblSalesTransactions[Salesperson ID],C13,tblSalesTransactions[Date],">="&DATE(YEAR(A13),MONTH(A13),1),tblSalesTransactions[Date],"<"&EDATE(A13,1)) -> 404000 | H13: =G13-F13 -> -1496000 | I13: =IFERROR(G13/F13,0) -> 0.21263158 | J13: =IF(I13>='02_Control_Panel'!$B$8,"Achieved",IF(I13>='02_Control_Panel'!$B$7,"Near Target","Below Target")) -> Below Target
... A145: =DATE(2026,B145,1) -> 46357 | B145: =ROUNDUP(ROWS($B$2:B145)/12,0) -> 12 | C145: ="SP"&TEXT(MOD(ROWS($C$2:C145)-1,12)+1,"000") -> SP012 | D145: R004 | E145: C004 | F145: =SUMIFS(tblSalesTargets[Target Amount],tblSalesTargets[MonthYear],A145,tblSalesTargets[Salesperson ID],C145) -> 2280000 | G145: =SUMIFS(tblSalesTransactions[Sales Amount],tblSalesTransactions[Salesperson ID],C145,tblSalesTransactions[Date],">="&DATE(YEAR(A145),MONTH(A145),1),tblSalesTransactions[Date],"<"&EDATE(A145,1)) -> 415250 | H145: =G145-F145 -> -1864750 | I145: =IFERROR(G145/F145,0) -> 0.18212719 | J145: =IF(I145>='02_Control_Panel'!$B$8,"Achieved",IF(I145>='02_Control_Panel'!$B$7,"Near Target","Below Target")) -> Below Target
F146: =SUBTOTAL(109,tblPerformance[Target Amount]) -> 348075000 | G146: =SUBTOTAL(109,tblPerformance[Actual Sales]) -> 60255750 | H146: =SUBTOTAL(109,tblPerformance[SALES VARIANCE]) -> -287819250 | I146: =IFERROR(SUM(tblPerformance[Actual Sales])/SUM(tblPerformance[Target Amount]),0) -> 0.1731114

Sheet 13_Target_vs_Actual
A1: Target vs Actual Performance
A3: MonthYear | B3: Month No | C3: Salesperson ID | D3: RSM ID | E3: City ID | F3: Target Amount | G3: Actual Sales | H3: SALES VARIANCE | I3: Achievement % | J3: Performance Status | M3: Overall KPI | S3: 1 | T3: 2 | U3: 3 | V3: 4 | W3: 5 | X3: 6
A4: 46023 | B4: 1 | C4: SP001 | D4: R001 | E4: C001 | F4: =SUMIFS(tblSalesTargets[Target Amount],tblSalesTargets[MonthYear],A4,tblSalesTargets[Salesperson ID],C4) -> 2500000 | G4: =SUMIFS(tblSalesTransactions[Sales Amount],tblSalesTransactions[Salesperson ID],C4,tblSalesTransactions[Date],">="&A4,tblSalesTransactions[Date],"<"&EDATE(A4,1)) -> 350500 | H4: =G4-F4 -> -2149500 | I4: =IFERROR(G4/F4,0) -> 0.1402 | J4: =IF(I4>=1,"Achieved",IF(I4>=0.9,"Near Target","Below Target")) -> Below Target | M4: Total Target | N4: =SUM(tblTargetVsActual[Target Amount]) -> 348075000 | S4: =SUMIFS(tblSalesTargets[Target Amount],tblSalesTargets[MonthYear],A4,tblSalesTargets[Salesperson ID],C4) -> 2500000 | T4: =SUMIFS(tblSalesTransactions[Sales Amount],tblSalesTransactions[Salesperson ID],C4,tblSalesTransactions[Date],">="&A4,tblSalesTransactions[Date],"<"&EDATE(A4,1)) -> 350500 | U4: =F4 -> 2500000 | V4: =G4 -> 350500 | W4: =S4=U4 -> TRUE | X4: =T4=V4 -> TRUE
A5: 46023 | B5: 1 | C5: SP002 | D5: R001 | E5: C001 | F5: =SUMIFS(tblSalesTargets[Target Amount],tblSalesTargets[MonthYear],A5,tblSalesTargets[Salesperson ID],C5) -> 2300000 | G5: =SUMIFS(tblSalesTransactions[Sales Amount],tblSalesTransactions[Salesperson ID],C5,tblSalesTransactions[Date],">="&A5,tblSalesTransactions[Date],"<"&EDATE(A5,1)) -> 375000 | H5: =G5-F5 -> -1925000 | I5: =IFERROR(G5/F5,0) -> 0.16304348 | J5: =IF(I5>=1,"Achieved",IF(I5>=0.9,"Near Target","Below Target")) -> Below Target | M5: Total Actual Sales | N5: =SUM(tblTargetVsActual[Actual Sales]) -> 60255750 | S5: =SUMIFS(tblSalesTargets[Target Amount],tblSalesTargets[MonthYear],A5,tblSalesTargets[Salesperson ID],C5) -> 2300000 | T5: =SUMIFS(tblSalesTransactions[Sales Amount],tblSalesTransactions[Salesperson ID],C5,tblSalesTransactions[Date],">="&A5,tblSalesTransactions[Date],"<"&EDATE(A5,1)) -> 375000 | U5: =F5 -> 2300000 | V5: =G5 -> 375000 | W5: =S5=U5 -> TRUE | X5: =T5=V5 -> TRUE
A6: 46023 | B6: 1 | C6: SP003 | D6: R001 | E6: C001 | F6: =SUMIFS(tblSalesTargets[Target Amount],tblSalesTargets[MonthYear],A6,tblSalesTargets[Salesperson ID],C6) -> 2200000 | G6: =SUMIFS(tblSalesTransactions[Sales Amount],tblSalesTransactions[Salesperson ID],C6,tblSalesTransactions[Date],">="&A6,tblSalesTransactions[Date],"<"&EDATE(A6,1)) -> 371750 | H6: =G6-F6 -> -1828250 | I6: =IFERROR(G6/F6,0) -> 0.16897727 | J6: =IF(I6>=1,"Achieved",IF(I6>=0.9,"Near Target","Below Target")) -> Below Target | M6: Total Variance | N6: =N5-N4 -> -287819250 | S6: =SUMIFS(tblSalesTargets[Target Amount],tblSalesTargets[MonthYear],A6,tblSalesTargets[Salesperson ID],C6) -> 2200000 | T6: =SUMIFS(tblSalesTransactions[Sales Amount],tblSalesTransactions[Salesperson ID],C6,tblSalesTransactions[Date],">="&A6,tblSalesTransactions[Date],"<"&EDATE(A6,1)) -> 371750 | U6: =F6 -> 2200000 | V6: =G6 -> 371750 | W6: =S6=U6 -> TRUE | X6: =T6=V6 -> TRUE
A7: 46023 | B7: 1 | C7: SP004 | D7: R002 | E7: C002 | F7: =SUMIFS(tblSalesTargets[Target Amount],tblSalesTargets[MonthYear],A7,tblSalesTargets[Salesperson ID],C7) -> 2700000 | G7: =SUMIFS(tblSalesTransactions[Sales Amount],tblSalesTransactions[Salesperson ID],C7,tblSalesTransactions[Date],">="&A7,tblSalesTransactions[Date],"<"&EDATE(A7,1)) -> 648000 | H7: =G7-F7 -> -2052000 | I7: =IFERROR(G7/F7,0) -> 0.24 | J7: =IF(I7>=1,"Achieved",IF(I7>=0.9,"Near Target","Below Target")) -> Below Target | M7: Overall Achievement % | N7: =IFERROR(N5/N4,0) -> 0.1731114 | S7: =SUMIFS(tblSalesTargets[Target Amount],tblSalesTargets[MonthYear],A7,tblSalesTargets[Salesperson ID],C7) -> 2700000 | T7: =SUMIFS(tblSalesTransactions[Sales Amount],tblSalesTransactions[Salesperson ID],C7,tblSalesTransactions[Date],">="&A7,tblSalesTransactions[Date],"<"&EDATE(A7,1)) -> 648000 | U7: =F7 -> 2700000 | V7: =G7 -> 648000 | W7: =S7=U7 -> TRUE | X7: =T7=V7 -> TRUE
A8: 46023 | B8: 1 | C8: SP005 | D8: R002 | E8: C002 | F8: =SUMIFS(tblSalesTargets[Target Amount],tblSalesTargets[MonthYear],A8,tblSalesTargets[Salesperson ID],C8) -> 2500000 | G8: =SUMIFS(tblSalesTransactions[Sales Amount],tblSalesTransactions[Salesperson ID],C8,tblSalesTransactions[Date],">="&A8,tblSalesTransactions[Date],"<"&EDATE(A8,1)) -> 626000 | H8: =G8-F8 -> -1874000 | I8: =IFERROR(G8/F8,0) -> 0.2504 | J8: =IF(I8>=1,"Achieved",IF(I8>=0.9,"Near Target","Below Target")) -> Below Target | S8: =SUMIFS(tblSalesTargets[Target Amount],tblSalesTargets[MonthYear],A8,tblSalesTargets[Salesperson ID],C8) -> 2500000 | T8: =SUMIFS(tblSalesTransactions[Sales Amount],tblSalesTransactions[Salesperson ID],C8,tblSalesTransactions[Date],">="&A8,tblSalesTransactions[Date],"<"&EDATE(A8,1)) -> 626000 | U8: =F8 -> 2500000 | V8: =G8 -> 626000 | W8: =S8=U8 -> TRUE | X8: =T8=V8 -> TRUE
A9: 46023 | B9: 1 | C9: SP006 | D9: R002 | E9: C002 | F9: =SUMIFS(tblSalesTargets[Target Amount],tblSalesTargets[MonthYear],A9,tblSalesTargets[Salesperson ID],C9) -> 2300000 | G9: =SUMIFS(tblSalesTransactions[Sales Amount],tblSalesTransactions[Salesperson ID],C9,tblSalesTransactions[Date],">="&A9,tblSalesTransactions[Date],"<"&EDATE(A9,1)) -> 464500 | H9: =G9-F9 -> -1835500 | I9: =IFERROR(G9/F9,0) -> 0.20195652 | J9: =IF(I9>=1,"Achieved",IF(I9>=0.9,"Near Target","Below Target")) -> Below Target | S9: =SUMIFS(tblSalesTargets[Target Amount],tblSalesTargets[MonthYear],A9,tblSalesTargets[Salesperson ID],C9) -> 2300000 | T9: =SUMIFS(tblSalesTransactions[Sales Amount],tblSalesTransactions[Salesperson ID],C9,tblSalesTransactions[Date],">="&A9,tblSalesTransactions[Date],"<"&EDATE(A9,1)) -> 464500 | U9: =F9 -> 2300000 | V9: =G9 -> 464500 | W9: =S9=U9 -> TRUE | X9: =T9=V9 -> TRUE
A10: 46023 | B10: 1 | C10: SP007 | D10: R003 | E10: C003 | F10: =SUMIFS(tblSalesTargets[Target Amount],tblSalesTargets[MonthYear],A10,tblSalesTargets[Salesperson ID],C10) -> 2400000 | G10: =SUMIFS(tblSalesTransactions[Sales Amount],tblSalesTransactions[Salesperson ID],C10,tblSalesTransactions[Date],">="&A10,tblSalesTransactions[Date],"<"&EDATE(A10,1)) -> 638000 | H10: =G10-F10 -> -1762000 | I10: =IFERROR(G10/F10,0) -> 0.26583333 | J10: =IF(I10>=1,"Achieved",IF(I10>=0.9,"Near Target","Below Target")) -> Below Target | M10: MonthYear | N10: Target | O10: Actual Sales | P10: SALES Variance | Q10: Achievement % | S10: =SUMIFS(tblSalesTargets[Target Amount],tblSalesTargets[MonthYear],A10,tblSalesTargets[Salesperson ID],C10) -> 2400000 | T10: =SUMIFS(tblSalesTransactions[Sales Amount],tblSalesTransactions[Salesperson ID],C10,tblSalesTransactions[Date],">="&A10,tblSalesTransactions[Date],"<"&EDATE(A10,1)) -> 638000 | U10: =F10 -> 2400000 | V10: =G10 -> 638000 | W10: =S10=U10 -> TRUE | X10: =T10=V10 -> TRUE
A11: 46023 | B11: 1 | C11: SP008 | D11: R003 | E11: C003 | F11: =SUMIFS(tblSalesTargets[Target Amount],tblSalesTargets[MonthYear],A11,tblSalesTargets[Salesperson ID],C11) -> 2200000 | G11: =SUMIFS(tblSalesTransactions[Sales Amount],tblSalesTransactions[Salesperson ID],C11,tblSalesTransactions[Date],">="&A11,tblSalesTransactions[Date],"<"&EDATE(A11,1)) -> 591000 | H11: =G11-F11 -> -1609000 | I11: =IFERROR(G11/F11,0) -> 0.26863636 | J11: =IF(I11>=1,"Achieved",IF(I11>=0.9,"Near Target","Below Target")) -> Below Target | M11: =DATE(2026,1,1) -> 46023 | N11: =SUMIFS(tblTargetVsActual[Target Amount],tblTargetVsActual[MonthYear],M11) -> 27300000 | O11: =SUMIFS(tblTargetVsActual[Actual Sales],tblTargetVsActual[MonthYear],M11) -> 5691250 | P11: =O11-N11 -> -21608750 | Q11: =IFERROR(O11/N11,0) -> 0.2084707 | S11: =SUMIFS(tblSalesTargets[Target Amount],tblSalesTargets[MonthYear],A11,tblSalesTargets[Salesperson ID],C11) -> 2200000 | T11: =SUMIFS(tblSalesTransactions[Sales Amount],tblSalesTransactions[Salesperson ID],C11,tblSalesTransactions[Date],">="&A11,tblSalesTransactions[Date],"<"&EDATE(A11,1)) -> 591000 | U11: =F11 -> 2200000 | V11: =G11 -> 591000 | W11: =S11=U11 -> TRUE | X11: =T11=V11 -> TRUE
A12: 46023 | B12: 1 | C12: SP009 | D12: R003 | E12: C003 | F12: =SUMIFS(tblSalesTargets[Target Amount],tblSalesTargets[MonthYear],A12,tblSalesTargets[Salesperson ID],C12) -> 2100000 | G12: =SUMIFS(tblSalesTransactions[Sales Amount],tblSalesTransactions[Salesperson ID],C12,tblSalesTransactions[Date],">="&A12,tblSalesTransactions[Date],"<"&EDATE(A12,1)) -> 456000 | H12: =G12-F12 -> -1644000 | I12: =IFERROR(G12/F12,0) -> 0.21714286 | J12: =IF(I12>=1,"Achieved",IF(I12>=0.9,"Near Target","Below Target")) -> Below Target | M12: =EDATE(M11,1) -> 46054 | N12: =SUMIFS(tblTargetVsActual[Target Amount],tblTargetVsActual[MonthYear],M12) -> 28119000 | O12: =SUMIFS(tblTargetVsActual[Actual Sales],tblTargetVsActual[MonthYear],M12) -> 4273750 | P12: =O12-N12 -> -23845250 | Q12: =IFERROR(O12/N12,0) -> 0.15198798 | S12: =SUMIFS(tblSalesTargets[Target Amount],tblSalesTargets[MonthYear],A12,tblSalesTargets[Salesperson ID],C12) -> 2100000 | T12: =SUMIFS(tblSalesTransactions[Sales Amount],tblSalesTransactions[Salesperson ID],C12,tblSalesTransactions[Date],">="&A12,tblSalesTransactions[Date],"<"&EDATE(A12,1)) -> 456000 | U12: =F12 -> 2100000 | V12: =G12 -> 456000 | W12: =S12=U12 -> TRUE | X12: =T12=V12 -> TRUE
A13: 46023 | B13: 1 | C13: SP010 | D13: R004 | E13: C004 | F13: =SUMIFS(tblSalesTargets[Target Amount],tblSalesTargets[MonthYear],A13,tblSalesTargets[Salesperson ID],C13) -> 2200000 | G13: =SUMIFS(tblSalesTransactions[Sales Amount],tblSalesTransactions[Salesperson ID],C13,tblSalesTransactions[Date],">="&A13,tblSalesTransactions[Date],"<"&EDATE(A13,1)) -> 379500 | H13: =G13-F13 -> -1820500 | I13: =IFERROR(G13/F13,0) -> 0.1725 | J13: =IF(I13>=1,"Achieved",IF(I13>=0.9,"Near Target","Below Target")) -> Below Target | M13: =EDATE(M12,1) -> 46082 | N13: =SUMIFS(tblTargetVsActual[Target Amount],tblTargetVsActual[MonthYear],M13) -> 28665000 | O13: =SUMIFS(tblTargetVsActual[Actual Sales],tblTargetVsActual[MonthYear],M13) -> 4507750 | P13: =O13-N13 -> -24157250 | Q13: =IFERROR(O13/N13,0) -> 0.15725624 | S13: =SUMIFS(tblSalesTargets[Target Amount],tblSalesTargets[MonthYear],A13,tblSalesTargets[Salesperson ID],C13) -> 2200000 | T13: =SUMIFS(tblSalesTransactions[Sales Amount],tblSalesTransactions[Salesperson ID],C13,tblSalesTransactions[Date],">="&A13,tblSalesTransactions[Date],"<"&EDATE(A13,1)) -> 379500 | U13: =F13 -> 2200000 | V13: =G13 -> 379500 | W13: =S13=U13 -> TRUE | X13: =T13=V13 -> TRUE
A14: 46023 | B14: 1 | C14: SP011 | D14: R004 | E14: C004 | F14: =SUMIFS(tblSalesTargets[Target Amount],tblSalesTargets[MonthYear],A14,tblSalesTargets[Salesperson ID],C14) -> 2000000 | G14: =SUMIFS(tblSalesTransactions[Sales Amount],tblSalesTransactions[Salesperson ID],C14,tblSalesTransactions[Date],">="&A14,tblSalesTransactions[Date],"<"&EDATE(A14,1)) -> 387000 | H14: =G14-F14 -> -1613000 | I14: =IFERROR(G14/F14,0) -> 0.1935 | J14: =IF(I14>=1,"Achieved",IF(I14>=0.9,"Near Target","Below Target")) -> Below Target | M14: =EDATE(M13,1) -> 46113 | N14: =SUMIFS(tblTargetVsActual[Target Amount],tblTargetVsActual[MonthYear],M14) -> 26754000 | O14: =SUMIFS(tblTargetVsActual[Actual Sales],tblTargetVsActual[MonthYear],M14) -> 3900000 | P14: =O14-N14 -> -22854000 | Q14: =IFERROR(O14/N14,0) -> 0.14577259 | S14: =SUMIFS(tblSalesTargets[Target Amount],tblSalesTargets[MonthYear],A14,tblSalesTargets[Salesperson ID],C14) -> 2000000 | T14: =SUMIFS(tblSalesTransactions[Sales Amount],tblSalesTransactions[Salesperson ID],C14,tblSalesTransactions[Date],">="&A14,tblSalesTransactions[Date],"<"&EDATE(A14,1)) -> 387000 | U14: =F14 -> 2000000 | V14: =G14 -> 387000 | W14: =S14=U14 -> TRUE | X14: =T14=V14 -> TRUE
A15: 46023 | B15: 1 | C15: SP012 | D15: R004 | E15: C004 | F15: =SUMIFS(tblSalesTargets[Target Amount],tblSalesTargets[MonthYear],A15,tblSalesTargets[Salesperson ID],C15) -> 1900000 | G15: =SUMIFS(tblSalesTransactions[Sales Amount],tblSalesTransactions[Salesperson ID],C15,tblSalesTransactions[Date],">="&A15,tblSalesTransactions[Date],"<"&EDATE(A15,1)) -> 404000 | H15: =G15-F15 -> -1496000 | I15: =IFERROR(G15/F15,0) -> 0.21263158 | J15: =IF(I15>=1,"Achieved",IF(I15>=0.9,"Near Target","Below Target")) -> Below Target | M15: =EDATE(M14,1) -> 46143 | N15: =SUMIFS(tblTargetVsActual[Target Amount],tblTargetVsActual[MonthYear],M15) -> 27846000 | O15: =SUMIFS(tblTargetVsActual[Actual Sales],tblTargetVsActual[MonthYear],M15) -> 4602250 | P15: =O15-N15 -> -23243750 | Q15: =IFERROR(O15/N15,0) -> 0.16527508 | S15: =SUMIFS(tblSalesTargets[Target Amount],tblSalesTargets[MonthYear],A15,tblSalesTargets[Salesperson ID],C15) -> 1900000 | T15: =SUMIFS(tblSalesTransactions[Sales Amount],tblSalesTransactions[Salesperson ID],C15,tblSalesTransactions[Date],">="&A15,tblSalesTransactions[Date],"<"&EDATE(A15,1)) -> 404000 | U15: =F15 -> 1900000 | V15: =G15 -> 404000 | W15: =S15=U15 -> TRUE | X15: =T15=V15 -> TRUE
A16: 46054 | B16: 2 | C16: SP001 | D16: R001 | E16: C001 | F16: =SUMIFS(tblSalesTargets[Target Amount],tblSalesTargets[MonthYear],A16,tblSalesTargets[Salesperson ID],C16) -> 2575000 | G16: =SUMIFS(tblSalesTransactions[Sales Amount],tblSalesTransactions[Salesperson ID],C16,tblSalesTransactions[Date],">="&A16,tblSalesTransactions[Date],"<"&EDATE(A16,1)) -> 236500 | H16: =G16-F16 -> -2338500 | I16: =IFERROR(G16/F16,0) -> 0.09184466 | J16: =IF(I16>=1,"Achieved",IF(I16>=0.9,"Near Target","Below Target")) -> Below Target | M16: =EDATE(M15,1) -> 46174 | N16: =SUMIFS(tblTargetVsActual[Target Amount],tblTargetVsActual[MonthYear],M16) -> 29484000 | O16: =SUMIFS(tblTargetVsActual[Actual Sales],tblTargetVsActual[MonthYear],M16) -> 4729000 | P16: =O16-N16 -> -24755000 | Q16: =IFERROR(O16/N16,0) -> 0.16039208 | S16: =SUMIFS(tblSalesTargets[Target Amount],tblSalesTargets[MonthYear],A16,tblSalesTargets[Salesperson ID],C16) -> 2575000 | T16: =SUMIFS(tblSalesTransactions[Sales Amount],tblSalesTransactions[Salesperson ID],C16,tblSalesTransactions[Date],">="&A16,tblSalesTransactions[Date],"<"&EDATE(A16,1)) -> 236500 | U16: =F16 -> 2575000 | V16: =G16 -> 236500 | W16: =S16=U16 -> TRUE | X16: =T16=V16 -> TRUE
A17: 46054 | B17: 2 | C17: SP002 | D17: R001 | E17: C001 | F17: =SUMIFS(tblSalesTargets[Target Amount],tblSalesTargets[MonthYear],A17,tblSalesTargets[Salesperson ID],C17) -> 2369000 | G17: =SUMIFS(tblSalesTransactions[Sales Amount],tblSalesTransactions[Salesperson ID],C17,tblSalesTransactions[Date],">="&A17,tblSalesTransactions[Date],"<"&EDATE(A17,1)) -> 303500 | H17: =G17-F17 -> -2065500 | I17: =IFERROR(G17/F17,0) -> 0.12811313 | J17: =IF(I17>=1,"Achieved",IF(I17>=0.9,"Near Target","Below Target")) -> Below Target | M17: =EDATE(M16,1) -> 46204 | N17: =SUMIFS(tblTargetVsActual[Target Amount],tblTargetVsActual[MonthYear],M17) -> 28392000 | O17: =SUMIFS(tblTargetVsActual[Actual Sales],tblTargetVsActual[MonthYear],M17) -> 4432750 | P17: =O17-N17 -> -23959250 | Q17: =IFERROR(O17/N17,0) -> 0.15612673 | S17: =SUMIFS(tblSalesTargets[Target Amount],tblSalesTargets[MonthYear],A17,tblSalesTargets[Salesperson ID],C17) -> 2369000 | T17: =SUMIFS(tblSalesTransactions[Sales Amount],tblSalesTransactions[Salesperson ID],C17,tblSalesTransactions[Date],">="&A17,tblSalesTransactions[Date],"<"&EDATE(A17,1)) -> 303500 | U17: =F17 -> 2369000 | V17: =G17 -> 303500 | W17: =S17=U17 -> TRUE | X17: =T17=V17 -> TRUE
A18: 46054 | B18: 2 | C18: SP003 | D18: R001 | E18: C001 | F18: =SUMIFS(tblSalesTargets[Target Amount],tblSalesTargets[MonthYear],A18,tblSalesTargets[Salesperson ID],C18) -> 2266000 | G18: =SUMIFS(tblSalesTransactions[Sales Amount],tblSalesTransactions[Salesperson ID],C18,tblSalesTransactions[Date],">="&A18,tblSalesTransactions[Date],"<"&EDATE(A18,1)) -> 287250 | H18: =G18-F18 -> -1978750 | I18: =IFERROR(G18/F18,0) -> 0.12676523 | J18: =IF(I18>=1,"Achieved",IF(I18>=0.9,"Near Target","Below Target")) -> Below Target | M18: =EDATE(M17,1) -> 46235 | N18: =SUMIFS(tblTargetVsActual[Target Amount],tblTargetVsActual[MonthYear],M18) -> 28938000 | O18: =SUMIFS(tblTargetVsActual[Actual Sales],tblTargetVsActual[MonthYear],M18) -> 4931500 | P18: =O18-N18 -> -24006500 | Q18: =IFERROR(O18/N18,0) -> 0.17041606 | S18: =SUMIFS(tblSalesTargets[Target Amount],tblSalesTargets[MonthYear],A18,tblSalesTargets[Salesperson ID],C18) -> 2266000 | T18: =SUMIFS(tblSalesTransactions[Sales Amount],tblSalesTransactions[Salesperson ID],C18,tblSalesTransactions[Date],">="&A18,tblSalesTransactions[Date],"<"&EDATE(A18,1)) -> 287250 | U18: =F18 -> 2266000 | V18: =G18 -> 287250 | W18: =S18=U18 -> TRUE | X18: =T18=V18 -> TRUE
A19: 46054 | B19: 2 | C19: SP004 | D19: R002 | E19: C002 | F19: =SUMIFS(tblSalesTargets[Target Amount],tblSalesTargets[MonthYear],A19,tblSalesTargets[Salesperson ID],C19) -> 2781000 | G19: =SUMIFS(tblSalesTransactions[Sales Amount],tblSalesTransactions[Salesperson ID],C19,tblSalesTransactions[Date],">="&A19,tblSalesTransactions[Date],"<"&EDATE(A19,1)) -> 505500 | H19: =G19-F19 -> -2275500 | I19: =IFERROR(G19/F19,0) -> 0.18176915 | J19: =IF(I19>=1,"Achieved",IF(I19>=0.9,"Near Target","Below Target")) -> Below Target | M19: =EDATE(M18,1) -> 46266 | N19: =SUMIFS(tblTargetVsActual[Target Amount],tblTargetVsActual[MonthYear],M19) -> 29211000 | O19: =SUMIFS(tblTargetVsActual[Actual Sales],tblTargetVsActual[MonthYear],M19) -> 5190750 | P19: =O19-N19 -> -24020250 | Q19: =IFERROR(O19/N19,0) -> 0.17769847 | S19: =SUMIFS(tblSalesTargets[Target Amount],tblSalesTargets[MonthYear],A19,tblSalesTargets[Salesperson ID],C19) -> 2781000 | T19: =SUMIFS(tblSalesTransactions[Sales Amount],tblSalesTransactions[Salesperson ID],C19,tblSalesTransactions[Date],">="&A19,tblSalesTransactions[Date],"<"&EDATE(A19,1)) -> 505500 | U19: =F19 -> 2781000 | V19: =G19 -> 505500 | W19: =S19=U19 -> TRUE | X19: =T19=V19 -> TRUE
A20: 46054 | B20: 2 | C20: SP005 | D20: R002 | E20: C002 | F20: =SUMIFS(tblSalesTargets[Target Amount],tblSalesTargets[MonthYear],A20,tblSalesTargets[Salesperson ID],C20) -> 2575000 | G20: =SUMIFS(tblSalesTransactions[Sales Amount],tblSalesTransactions[Salesperson ID],C20,tblSalesTransactions[Date],">="&A20,tblSalesTransactions[Date],"<"&EDATE(A20,1)) -> 504000 | H20: =G20-F20 -> -2071000 | I20: =IFERROR(G20/F20,0) -> 0.19572816 | J20: =IF(I20>=1,"Achieved",IF(I20>=0.9,"Near Target","Below Target")) -> Below Target | M20: =EDATE(M19,1) -> 46296 | N20: =SUMIFS(tblTargetVsActual[Target Amount],tblTargetVsActual[MonthYear],M20) -> 30030000 | O20: =SUMIFS(tblTargetVsActual[Actual Sales],tblTargetVsActual[MonthYear],M20) -> 5458250 | P20: =O20-N20 -> -24571750 | Q20: =IFERROR(O20/N20,0) -> 0.18175991 | S20: =SUMIFS(tblSalesTargets[Target Amount],tblSalesTargets[MonthYear],A20,tblSalesTargets[Salesperson ID],C20) -> 2575000 | T20: =SUMIFS(tblSalesTransactions[Sales Amount],tblSalesTransactions[Salesperson ID],C20,tblSalesTransactions[Date],">="&A20,tblSalesTransactions[Date],"<"&EDATE(A20,1)) -> 504000 | U20: =F20 -> 2575000 | V20: =G20 -> 504000 | W20: =S20=U20 -> TRUE | X20: =T20=V20 -> TRUE
A21: 46054 | B21: 2 | C21: SP006 | D21: R002 | E21: C002 | F21: =SUMIFS(tblSalesTargets[Target Amount],tblSalesTargets[MonthYear],A21,tblSalesTargets[Salesperson ID],C21) -> 2369000 | G21: =SUMIFS(tblSalesTransactions[Sales Amount],tblSalesTransactions[Salesperson ID],C21,tblSalesTransactions[Date],">="&A21,tblSalesTransactions[Date],"<"&EDATE(A21,1)) -> 329000 | H21: =G21-F21 -> -2040000 | I21: =IFERROR(G21/F21,0) -> 0.13887716 | J21: =IF(I21>=1,"Achieved",IF(I21>=0.9,"Near Target","Below Target")) -> Below Target | M21: =EDATE(M20,1) -> 46327 | N21: =SUMIFS(tblTargetVsActual[Target Amount],tblTargetVsActual[MonthYear],M21) -> 30576000 | O21: =SUMIFS(tblTargetVsActual[Actual Sales],tblTargetVsActual[MonthYear],M21) -> 5931000 | P21: =O21-N21 -> -24645000 | Q21: =IFERROR(O21/N21,0) -> 0.19397567 | S21: =SUMIFS(tblSalesTargets[Target Amount],tblSalesTargets[MonthYear],A21,tblSalesTargets[Salesperson ID],C21) -> 2369000 | T21: =SUMIFS(tblSalesTransactions[Sales Amount],tblSalesTransactions[Salesperson ID],C21,tblSalesTransactions[Date],">="&A21,tblSalesTransactions[Date],"<"&EDATE(A21,1)) -> 329000 | U21: =F21 -> 2369000 | V21: =G21 -> 329000 | W21: =S21=U21 -> TRUE | X21: =T21=V21 -> TRUE
A22: 46054 | B22: 2 | C22: SP007 | D22: R003 | E22: C003 | F22: =SUMIFS(tblSalesTargets[Target Amount],tblSalesTargets[MonthYear],A22,tblSalesTargets[Salesperson ID],C22) -> 2472000 | G22: =SUMIFS(tblSalesTransactions[Sales Amount],tblSalesTransactions[Salesperson ID],C22,tblSalesTransactions[Date],">="&A22,tblSalesTransactions[Date],"<"&EDATE(A22,1)) -> 486000 | H22: =G22-F22 -> -1986000 | I22: =IFERROR(G22/F22,0) -> 0.19660194 | J22: =IF(I22>=1,"Achieved",IF(I22>=0.9,"Near Target","Below Target")) -> Below Target | M22: =EDATE(M21,1) -> 46357 | N22: =SUMIFS(tblTargetVsActual[Target Amount],tblTargetVsActual[MonthYear],M22) -> 32760000 | O22: =SUMIFS(tblTargetVsActual[Actual Sales],tblTargetVsActual[MonthYear],M22) -> 6607500 | P22: =O22-N22 -> -26152500 | Q22: =IFERROR(O22/N22,0) -> 0.20169414 | S22: =SUMIFS(tblSalesTargets[Target Amount],tblSalesTargets[MonthYear],A22,tblSalesTargets[Salesperson ID],C22) -> 2472000 | T22: =SUMIFS(tblSalesTransactions[Sales Amount],tblSalesTransactions[Salesperson ID],C22,tblSalesTransactions[Date],">="&A22,tblSalesTransactions[Date],"<"&EDATE(A22,1)) -> 486000 | U22: =F22 -> 2472000 | V22: =G22 -> 486000 | W22: =S22=U22 -> TRUE | X22: =T22=V22 -> TRUE
A23: 46054 | B23: 2 | C23: SP008 | D23: R003 | E23: C003 | F23: =SUMIFS(tblSalesTargets[Target Amount],tblSalesTargets[MonthYear],A23,tblSalesTargets[Salesperson ID],C23) -> 2266000 | G23: =SUMIFS(tblSalesTransactions[Sales Amount],tblSalesTransactions[Salesperson ID],C23,tblSalesTransactions[Date],">="&A23,tblSalesTransactions[Date],"<"&EDATE(A23,1)) -> 496500 | H23: =G23-F23 -> -1769500 | I23: =IFERROR(G23/F23,0) -> 0.21910856 | J23: =IF(I23>=1,"Achieved",IF(I23>=0.9,"Near Target","Below Target")) -> Below Target | S23: =SUMIFS(tblSalesTargets[Target Amount],tblSalesTargets[MonthYear],A23,tblSalesTargets[Salesperson ID],C23) -> 2266000 | T23: =SUMIFS(tblSalesTransactions[Sales Amount],tblSalesTransactions[Salesperson ID],C23,tblSalesTransactions[Date],">="&A23,tblSalesTransactions[Date],"<"&EDATE(A23,1)) -> 496500 | U23: =F23 -> 2266000 | V23: =G23 -> 496500 | W23: =S23=U23 -> TRUE | X23: =T23=V23 -> TRUE
A24: 46054 | B24: 2 | C24: SP009 | D24: R003 | E24: C003 | F24: =SUMIFS(tblSalesTargets[Target Amount],tblSalesTargets[MonthYear],A24,tblSalesTargets[Salesperson ID],C24) -> 2163000 | G24: =SUMIFS(tblSalesTransactions[Sales Amount],tblSalesTransactions[Salesperson ID],C24,tblSalesTransactions[Date],">="&A24,tblSalesTransactions[Date],"<"&EDATE(A24,1)) -> 302500 | H24: =G24-F24 -> -1860500 | I24: =IFERROR(G24/F24,0) -> 0.13985206 | J24: =IF(I24>=1,"Achieved",IF(I24>=0.9,"Near Target","Below Target")) -> Below Target | S24: =SUMIFS(tblSalesTargets[Target Amount],tblSalesTargets[MonthYear],A24,tblSalesTargets[Salesperson ID],C24) -> 2163000 | T24: =SUMIFS(tblSalesTransactions[Sales Amount],tblSalesTransactions[Salesperson ID],C24,tblSalesTransactions[Date],">="&A24,tblSalesTransactions[Date],"<"&EDATE(A24,1)) -> 302500 | U24: =F24 -> 2163000 | V24: =G24 -> 302500 | W24: =S24=U24 -> TRUE | X24: =T24=V24 -> TRUE
A25: 46054 | B25: 2 | C25: SP010 | D25: R004 | E25: C004 | F25: =SUMIFS(tblSalesTargets[Target Amount],tblSalesTargets[MonthYear],A25,tblSalesTargets[Salesperson ID],C25) -> 2266000 | G25: =SUMIFS(tblSalesTransactions[Sales Amount],tblSalesTransactions[Salesperson ID],C25,tblSalesTransactions[Date],">="&A25,tblSalesTransactions[Date],"<"&EDATE(A25,1)) -> 272500 | H25: =G25-F25 -> -1993500 | I25: =IFERROR(G25/F25,0) -> 0.12025596 | J25: =IF(I25>=1,"Achieved",IF(I25>=0.9,"Near Target","Below Target")) -> Below Target | S25: =SUMIFS(tblSalesTargets[Target Amount],tblSalesTargets[MonthYear],A25,tblSalesTargets[Salesperson ID],C25) -> 2266000 | T25: =SUMIFS(tblSalesTransactions[Sales Amount],tblSalesTransactions[Salesperson ID],C25,tblSalesTransactions[Date],">="&A25,tblSalesTransactions[Date],"<"&EDATE(A25,1)) -> 272500 | U25: =F25 -> 2266000 | V25: =G25 -> 272500 | W25: =S25=U25 -> TRUE | X25: =T25=V25 -> TRUE
